Workbook

Sheet Itinerários RJ por transportado
A1: Transportadora | B1: Rota | C1: Prazo
A2: SER TRANSPORTES DE CARGAS | B2: RJ03FIXO | C2: 48h
A3: TRANSPORTADORA ALMEIDA DE MARILIA LTDA | B3: RJ03 | C3: 48h
A4: TRANSPORTADORA ALMEIDA DE MARILIA LTDA | B4: RJKA | C4: 48h
A5: TRANSPORTADORA ALMEIDA DE MARILIA LTDA | B5: RJKAFIXO | C5: 48h
A6: CARSTEN | B6: RJ03FIXO | C6: 48h
A7: CARSTEN | B7: RJKAFIXO | C7: 48h
A8: SP MODAL TRANSPORTES LTDA | B8: RJ01 | C8: 48h
A9: SP MODAL TRANSPORTES LTDA | B9: RJ02 | C9: 48h
A10: SP MODAL TRANSPORTES LTDA | B10: RJ03 | C10: 48h
A11: SP MODAL TRANSPORTES LTDA | B11: RJ03FIXO | C11: 48h
A12: SP MODAL TRANSPORTES LTDA | B12: RJ04 | C12: 48h
... A21: AJBORGES TRANSPORTE | B21: RJ03FIXO | C21: 48h
A22: TRANSMARONI TRANSPORTES BRASIL RODOVIARIOS LTDA RJ03 | C22: 48h
A23: TRANSMARONI TRANSPORTES BRASIL RODOVIARIOS LTDA RJ03FIXO | C23: 48h
A24: MANOEL MESSIAS GOMES TRANSPORTES EPP | B24: RJ01 | C24: 48h
A25: MANOEL MESSIAS GOMES TRANSPORTES EPP | B25: RJ01FIXO | C25: 48h
A26: MANOEL MESSIAS GOMES TRANSPORTES EPP | B26: RJ02 | C26: 48h
A27: MANOEL MESSIAS GOMES TRANSPORTES EPP | B27: RJ02FIXO | C27: 48h
A28: MANOEL MESSIAS GOMES TRANSPORTES EPP | B28: RJ03 | C28: 48h
A29: MANOEL MESSIAS GOMES TRANSPORTES EPP | B29: RJ03FIXO | C29: 48h
A30: MANOEL MESSIAS GOMES TRANSPORTES EPP | B30: RJ04 | C30: 48h
A31: MANOEL MESSIAS GOMES TRANSPORTES EPP | B31: RJ04FIXO | C31: 48h
A32: MANOEL MESSIAS GOMES TRANSPORTES EPP | B32: RJ05 | C32: 48h
A33: MANOEL MESSIAS GOMES TRANSPORTES EPP | B33: RJ05FIXO | C33: 48h
A34: MANOEL MESSIAS GOMES TRANSPORTES EPP | B34: RJ06 | C34: 48h
A35: MANOEL MESSIAS GOMES TRANSPORTES EPP | B35: RJ06FIXO | C35: 48h
... A643: TRANSMAGNA TRANSPORTES LTDA | B643: RJ03FIXO | C643: 48h

Sheet Itinerários por transportadora 
A1: Transportadora | B1: Rota | C1: Prazo
A2: SER TRANSPORTES DE CARGAS | B2: SP02FIXO | C2: 48h
A3: SER TRANSPORTES DE CARGAS | B3: SP03FIXO | C3: 48h
A4: SER TRANSPORTES DE CARGAS | B4: SP04FIXO | C4: 48h
A5: SER TRANSPORTES DE CARGAS | B5: SP05FIXO | C5: 48h
A6: SER TRANSPORTES DE CARGAS | B6: SP06FIXO | C6: 48h
A7: SER TRANSPORTES DE CARGAS | B7: SP07FIXO | C7: 48h
A8: SER TRANSPORTES DE CARGAS | B8: SP08FIXO | C8: 48h
A9: SER TRANSPORTES DE CARGAS | B9: SP09FIXO | C9: 48h
A10: SER TRANSPORTES DE CARGAS | B10: SP10FIXO | C10: 48h
A11: SER TRANSPORTES DE CARGAS | B11: SP11FIXO | C11: 48h
A12: SER TRANSPORTES DE CARGAS | B12: SP12FIXO | C12: 48h
... A813: ARLINDO FRANCISCO DE OLIVEIRA | B813: SP30 | C813: 48h
A814: TEREZINHA MUNIZ DA CUNHA DAS CHAGAS 04145032870 SP02 | C814: 48h
A815: TEREZINHA MUNIZ DA CUNHA DAS CHAGAS 04145032870 SP07 | C815: 48h
A816: TEREZINHA MUNIZ DA CUNHA DAS CHAGAS 04145032870 SP09 | C816: 48h
A817: TEREZINHA MUNIZ DA CUNHA DAS CHAGAS 04145032870 SP12 | C817: 48h
A818: TEREZINHA MUNIZ DA CUNHA DAS CHAGAS 04145032870 SP16 | C818: 48h
A819: TEREZINHA MUNIZ DA CUNHA DAS CHAGAS 04145032870 SP17 | C819: 48h
A820: TEREZINHA MUNIZ DA CUNHA DAS CHAGAS 04145032870 SP20 | C820: 48h
A821: TEREZINHA MUNIZ DA CUNHA DAS CHAGAS 04145032870 SP23 | C821: 48h
A822: TEREZINHA MUNIZ DA CUNHA DAS CHAGAS 04145032870 SP24 | C822: 48h
A823: TEREZINHA MUNIZ DA CUNHA DAS CHAGAS 04145032870 SP25 | C823: 48h
A824: TEREZINHA MUNIZ DA CUNHA DAS CHAGAS 04145032870 SP30 | C824: 48h
A825: LOGMAXI MOVIMENTACAO E LOGISTICA LTDA | B825: SPDED | C825: 48h
A826: JOAQUIM AUGUSTO PEREIRA JUNIOR 03268463878 | B826: SP04 | C826: 48h
A827: JOAQUIM AUGUSTO PEREIRA JUNIOR 03268463878 | B827: SP04FIXO | C827: 48h
A828: GR TRANSPORTE RODOVIÁRIO DE CARGAS EIRELI | B828: SP01FIXO | C828: 48h
A829: GR TRANSPORTE RODOVIÁRIO DE CARGAS EIRELI | B829: SP02FIXO | C829: 48h
A830: GR TRANSPORTE RODOVIÁRIO DE CARGAS EIRELI | B830: SP07FIXO | C830: 48h
A831: GR TRANSPORTE RODOVIÁRIO DE CARGAS EIRELI | B831: SP09FIXO | C831: 48h
A832: GR TRANSPORTE RODOVIÁRIO DE CARGAS EIRELI | B832: SP13FIXO | C832: 48h
A833: GR TRANSPORTE RODOVIÁRIO DE CARGAS EIRELI | B833: SP14FIXO | C833: 48h
A834: GR TRANSPORTE RODOVIÁRIO DE CARGAS EIRELI | B834: SP15FIXO | C834: 48h
A835: GR TRANSPORTE RODOVIÁRIO DE CARGAS EIRELI | B835: SP19FIXO | C835: 48h
A836: GR TRANSPORTE RODOVIÁRIO DE CARGAS EIRELI | B836: SP21FIXO | C836: 48h
... A1000: ODECIO SALIDO FILHO 17406079885 | B1000: SP02 | C1000: 48h

Sheet Itinerários MG por transportado
A1: Transportadora | B1: Rota | C1: Prazo
A2: SER TRANSPORTES DE CARGAS | B2: MG08FIXO | C2: 48h
A3: TRANSPORTADORA ALMEIDA DE MARILIA LTDA | B3: MG02 | C3: 48h
A4: TRANSPORTADORA ALMEIDA DE MARILIA LTDA | B4: MG02FIXO | C4: 48h
A5: TRANSPORTADORA ALMEIDA DE MARILIA LTDA | B5: MG14 | C5: 96h
A6: TRANSPORTADORA ALMEIDA DE MARILIA LTDA | B6: MG14FIXO | C6: 96h
A7: TRANSPORTADORA ALMEIDA DE MARILIA LTDA | B7: MGKA | C7: 48h
A8: SP MODAL TRANSPORTES LTDA | B8: MG01 | C8: 48h
A9: SP MODAL TRANSPORTES LTDA | B9: MG02 | C9: 48h
A10: SP MODAL TRANSPORTES LTDA | B10: MG03 | C10: 48h
A11: SP MODAL TRANSPORTES LTDA | B11: MG04 | C11: 48h
A12: SP MODAL TRANSPORTES LTDA | B12: MG05 | C12: 48h
... A34: AJBORGES TRANSPORTE | B34: MG10FIXO | C34: 48h
A35: TRANSMARONI TRANSPORTES BRASIL RODOVIARIOS LTDA MG02 | C35: 48h
A36: MANOEL MESSIAS GOMES TRANSPORTES EPP | B36: MG01 | C36: 48h
A37: MANOEL MESSIAS GOMES TRANSPORTES EPP | B37: MG01FIXO | C37: 48h
A38: MANOEL MESSIAS GOMES TRANSPORTES EPP | B38: MG02 | C38: 48h
A39: MANOEL MESSIAS GOMES TRANSPORTES EPP | B39: MG02FIXO | C39: 48h
A40: MANOEL MESSIAS GOMES TRANSPORTES EPP | B40: MG03 | C40: 48h
A41: MANOEL MESSIAS GOMES TRANSPORTES EPP | B41: MG03FIXO | C41: 48h
A42: MANOEL MESSIAS GOMES TRANSPORTES EPP | B42: MG04 | C42: 48h
A43: MANOEL MESSIAS GOMES TRANSPORTES EPP | B43: MG04FIXO | C43: 48h
A44: MANOEL MESSIAS GOMES TRANSPORTES EPP | B44: MG05 | C44: 48h
A45: MANOEL MESSIAS GOMES TRANSPORTES EPP | B45: MG05FIXO | C45: 48h
A46: MANOEL MESSIAS GOMES TRANSPORTES EPP | B46: MG06 | C46: 48h
A47: MANOEL MESSIAS GOMES TRANSPORTES EPP | B47: MG06FIXO | C47: 48h
... A984: TRANSPORTADORA BASAN LTDA | B984: MGKA | C984: 48h

Sheet Itinerários ES por transportado
A1: Transportadora | B1: Rota | C1: Prazo
A2: SP MODAL TRANSPORTES LTDA | B2: ES01 | C2: 48h
A3: SP MODAL TRANSPORTES LTDA | B3: ES02 | C3: 48h
A4: SP MODAL TRANSPORTES LTDA | B4: ES03 | C4: 48h
A5: SP MODAL TRANSPORTES LTDA | B5: ES03FIXO | C5: 48h
A6: SP MODAL TRANSPORTES LTDA | B6: ES04 | C6: 48h
A7: AJBORGES TRANSPORTE | B7: ES01 | C7: 48h
A8: AJBORGES TRANSPORTE | B8: ES01FIXO | C8: 48h
A9: AJBORGES TRANSPORTE | B9: ES03 | C9: 48h
A10: AJBORGES TRANSPORTE | B10: ES03FIXO | C10: 48h
A11: MANOEL MESSIAS GOMES TRANSPORTES EPP | B11: ES01 | C11: 48h
A12: MANOEL MESSIAS GOMES TRANSPORTES EPP | B12: ES01FIXO | C12: 48h
... A294: 62.098.575 JOAO PEREIRA CASTRO | B294: ES04 | C294: 48h

Sheet Planilha1
A1: Transportadora | B1: Estado | C1: Cadastrado | D1: Não cadastrado | E1: Prazo
A2: =VLOOKUP('Itinerários por transportadora '!A898,'Itinerários por transportadora '!A:A,1,0) -> 36.232.091 HILTON CESAR LEONEL | B2: =LEFT(VLOOKUP(A2,'Itinerários por transportadora '!A:B,2,0),2) -> SP | C2: FALSE | D2: TRUE | F2: =IF(C2=FALSE,FALSE,TRUE) -> FALSE
A3: =VLOOKUP('Itinerários RJ por transportado'!A428,'Itinerários RJ por transportado'!A:A,1,0) -> 36.232.091 HILTON CESAR LEONEL | B3: =LEFT(VLOOKUP(A3,Itinerários_RJ_por_transportadora_pdf[[Transportadora]:[Rota]],2,0),2) -> RJ | C3: FALSE | D3: TRUE | F3: =IF(C3=FALSE,FALSE,TRUE) -> FALSE
A4: =VLOOKUP('Itinerários ES por transportado'!A197,'Itinerários ES por transportado'!A:A,1,0) -> 36.232.091 HILTON CESAR LEONEL | B4: =LEFT(VLOOKUP(A4,Itinerários_ES_por_transportadora_pdf[[Transportadora]:[Rota]],2,0),2) -> ES | C4: FALSE | D4: TRUE | F4: =IF(C4=FALSE,FALSE,TRUE) -> FALSE
A5: =VLOOKUP('Itinerários MG por transportado'!A722,'Itinerários MG por transportado'!A:A,1,0) -> 36.232.091 HILTON CESAR LEONEL | B5: =LEFT(VLOOKUP(A5,'Itinerários MG por transportado'!A:B,2,0),2) -> MG | C5: FALSE | D5: TRUE | F5: =IF(C5=FALSE,FALSE,TRUE) -> FALSE
A6: =VLOOKUP('Itinerários RJ por transportado'!A555,'Itinerários RJ por transportado'!A:A,1,0) -> 53.540.060 LUCIA NUNES DE SIQUEIRA CASTRO | B6: =LEFT(VLOOKUP(A6,Itinerários_RJ_por_transportadora_pdf[[Transportadora]:[Rota]],2,0),2) -> RJ | C6: FALSE | D6: TRUE | F6: =IF(C6=FALSE,FALSE,TRUE) -> FALSE
A7: =VLOOKUP('Itinerários ES por transportado'!A253,'Itinerários ES por transportado'!A:A,1,0) -> 53.540.060 LUCIA NUNES DE SIQUEIRA CASTRO | B7: =LEFT(VLOOKUP(A7,Itinerários_ES_por_transportadora_pdf[[Transportadora]:[Rota]],2,0),2) -> ES | C7: FALSE | D7: TRUE | F7: =IF(C7=FALSE,FALSE,TRUE) -> FALSE
A8: =VLOOKUP('Itinerários MG por transportado'!A938,'Itinerários MG por transportado'!A:A,1,0) -> 53.540.060 LUCIA NUNES DE SIQUEIRA CASTRO | B8: =LEFT(VLOOKUP(A8,'Itinerários MG por transportado'!A:B,2,0),2) -> MG | C8: FALSE | D8: TRUE | F8: =IF(C8=FALSE,FALSE,TRUE) -> FALSE
A9: =VLOOKUP('Itinerários RJ por transportado'!A586,'Itinerários RJ por transportado'!A:A,1,0) -> 54.792.392 RAYSSA OLIVEIRA SALES | B9: =LEFT(VLOOKUP(A9,Itinerários_RJ_por_transportadora_pdf[[Transportadora]:[Rota]],2,0),2) -> RJ | C9: FALSE | D9: TRUE | F9: =IF(C9=FALSE,FALSE,TRUE) -> FALSE
A10: =VLOOKUP('Itinerários ES por transportado'!A275,'Itinerários ES por transportado'!A:A,1,0) -> 54.792.392 RAYSSA OLIVEIRA SALES | B10: =LEFT(VLOOKUP(A10,Itinerários_ES_por_transportadora_pdf[[Transportadora]:[Rota]],2,0),2) -> ES | C10: FALSE | D10: TRUE | F10: =IF(C10=FALSE,FALSE,TRUE) -> FALSE
A11: =VLOOKUP('Itinerários RJ por transportado'!A630,'Itinerários RJ por transportado'!A:A,1,0) -> 58.622.244 ISSAO TOYODA | B11: =LEFT(VLOOKUP(A11,Itinerários_RJ_por_transportadora_pdf[[Transportadora]:[Rota]],2,0),2) -> RJ | C11: FALSE | D11: TRUE | F11: =IF(C11=FALSE,FALSE,TRUE) -> FALSE
A12: =VLOOKUP('Itinerários RJ por transportado'!A632,'Itinerários RJ por transportado'!A:A,1,0) -> 62.098.575 JOAO PEREIRA CASTRO | B12: =LEFT(VLOOKUP(A12,Itinerários_RJ_por_transportadora_pdf[[Transportadora]:[Rota]],2,0),2) -> RJ | C12: FALSE | D12: TRUE | F12: =IF(C12=FALSE,FALSE,TRUE) -> FALSE
A13: =VLOOKUP('Itinerários ES por transportado'!A291,'Itinerários ES por transportado'!A:A,1,0) -> 62.098.575 JOAO PEREIRA CASTRO | B13: =LEFT(VLOOKUP(A13,Itinerários_ES_por_transportadora_pdf[[Transportadora]:[Rota]],2,0),2) -> ES | C13: FALSE | D13: TRUE | F13: =IF(C13=FALSE,FALSE,TRUE) -> FALSE
A14: =VLOOKUP('Itinerários por transportadora '!A96,'Itinerários por transportadora '!A:A,1,0) -> AJBORGES TRANSPORTE | B14: =LEFT(VLOOKUP(A14,'Itinerários por transportadora '!A:B,2,0),2) -> SP | C14: FALSE | D14: TRUE | F14: =IF(C14=FALSE,FALSE,TRUE) -> FALSE
A15: =VLOOKUP('Itinerários RJ por transportado'!A20,'Itinerários RJ por transportado'!A:A,1,0) -> AJBORGES TRANSPORTE | B15: =LEFT(VLOOKUP(A15,Itinerários_RJ_por_transportadora_pdf[[Transportadora]:[Rota]],2,0),2) -> RJ | C15: FALSE | D15: TRUE | F15: =IF(C15=FALSE,FALSE,TRUE) -> FALSE
A16: =VLOOKUP('Itinerários ES por transportado'!A7,'Itinerários ES por transportado'!A:A,1,0) -> AJBORGES TRANSPORTE | B16: =LEFT(VLOOKUP(A16,Itinerários_ES_por_transportadora_pdf[[Transportadora]:[Rota]],2,0),2) -> ES | C16: FALSE | D16: TRUE | F16: =IF(C16=FALSE,FALSE,TRUE) -> FALSE
A17: =VLOOKUP('Itinerários MG por transportado'!A25,'Itinerários MG por transportado'!A:A,1,0) -> AJBORGES TRANSPORTE | B17: =LEFT(VLOOKUP(A17,'Itinerários MG por transportado'!A:B,2,0),2) -> MG | C17: FALSE | D17: TRUE | F17: =IF(C17=FALSE,FALSE,TRUE) -> FALSE
A18: =VLOOKUP('Itinerários por transportadora '!A715,'Itinerários por transportadora '!A:A,1,0) -> APARECIDO TAVARES TRANSPORTES ME | B18: =LEFT(VLOOKUP(A18,'Itinerários por transportadora '!A:B,2,0),2) -> SP | C18: FALSE | D18: TRUE | F18: =IF(C18=FALSE,FALSE,TRUE) -> FALSE
A19: =VLOOKUP('Itinerários RJ por transportado'!A328,'Itinerários RJ por transportado'!A:A,1,0) -> APARECIDO TAVARES TRANSPORTES ME | B19: =LEFT(VLOOKUP(A19,Itinerários_RJ_por_transportadora_pdf[[Transportadora]:[Rota]],2,0),2) -> RJ | C19: FALSE | D19: TRUE | F19: =IF(C19=FALSE,FALSE,TRUE) -> FALSE
A20: =VLOOKUP('Itinerários ES por transportado'!A150,'Itinerários ES por transportado'!A:A,1,0) -> APARECIDO TAVARES TRANSPORTES ME | B20: =LEFT(VLOOKUP(A20,Itinerários_ES_por_transportadora_pdf[[Transportadora]:[Rota]],2,0),2) -> ES | C20: FALSE | D20: TRUE | F20: =IF(C20=FALSE,FALSE,TRUE) -> FALSE
A21: =VLOOKUP('Itinerários MG por transportado'!A554,'Itinerários MG por transportado'!A:A,1,0) -> APARECIDO TAVARES TRANSPORTES ME | B21: =LEFT(VLOOKUP(A21,'Itinerários MG por transportado'!A:B,2,0),2) -> MG | C21: FALSE | D21: TRUE | F21: =IF(C21=FALSE,FALSE,TRUE) -> FALSE
A22: =VLOOKUP('Itinerários RJ por transportado'!A583,'Itinerários RJ por transportado'!A:A,1,0) -> ARANAO TRANSPORTES RODOVIARIOS LTDA | B22: =LEFT(VLOOKUP(A22,Itinerários_RJ_por_transportadora_pdf[[Transportadora]:[Rota]],2,0),2) -> RJ | C22: FALSE | D22: TRUE | F22: =IF(C22=FALSE,FALSE,TRUE) -> FALSE
A23: =VLOOKUP('Itinerários ES por transportado'!A269,'Itinerários ES por transportado'!A:A,1,0) -> ARANAO TRANSPORTES RODOVIARIOS LTDA | B23: =LEFT(VLOOKUP(A23,Itinerários_ES_por_transportadora_pdf[[Transportadora]:[Rota]],2,0),2) -> ES | C23: FALSE | D23: TRUE | F23: =IF(C23=FALSE,FALSE,TRUE) -> FALSE
A24: =VLOOKUP('Itinerários por transportadora '!A803,'Itinerários por transportadora '!A:A,1,0) -> ARLINDO FRANCISCO DE OLIVEIRA | B24: =LEFT(VLOOKUP(A24,'Itinerários por transportadora '!A:B,2,0),2) -> SP | C24: FALSE | D24: TRUE | F24: =IF(C24=FALSE,FALSE,TRUE) -> FALSE
A25: =VLOOKUP('Itinerários RJ por transportado'!A378,'Itinerários RJ por transportado'!A:A,1,0) -> ARLINDO FRANCISCO DE OLIVEIRA | B25: =LEFT(VLOOKUP(A25,Itinerários_RJ_por_transportadora_pdf[[Transportadora]:[Rota]],2,0),2) -> RJ | C25: FALSE | D25: TRUE | F25: =IF(C25=FALSE,FALSE,TRUE) -> FALSE
A26: =VLOOKUP('Itinerários ES por transportado'!A170,'Itinerários ES por transportado'!A:A,1,0) -> ARLINDO FRANCISCO DE OLIVEIRA | B26: =LEFT(VLOOKUP(A26,Itinerários_ES_por_transportadora_pdf[[Transportadora]:[Rota]],2,0),2) -> ES | C26: FALSE | D26: TRUE | F26: =IF(C26=FALSE,FALSE,TRUE) -> FALSE
A27: =VLOOKUP('Itinerários MG por transportado'!A641,'Itinerários MG por transportado'!A:A,1,0) -> ARLINDO FRANCISCO DE OLIVEIRA | B27: =LEFT(VLOOKUP(A27,'Itinerários MG por transportado'!A:B,2,0),2) -> MG | C27: FALSE | D27: TRUE | F27: =IF(C27=FALSE,FALSE,TRUE) -> FALSE
A28: =VLOOKUP('Itinerários por transportadora '!A733,'Itinerários por transportadora '!A:A,1,0) -> ARNALDO BENEDITO AMORIM - ME | B28: =LEFT(VLOOKUP(A28,'Itinerários por transportadora '!A:B,2,0),2) -> SP | C28: FALSE | D28: TRUE | F28: =IF(C28=FALSE,FALSE,TRUE) -> FALSE
A29: =VLOOKUP('Itinerários RJ por transportado'!A338,'Itinerários RJ por transportado'!A:A,1,0) -> ARNALDO BENEDITO AMORIM - ME | B29: =LEFT(VLOOKUP(A29,Itinerários_RJ_por_transportadora_pdf[[Transportadora]:[Rota]],2,0),2) -> RJ | C29: FALSE | D29: TRUE | F29: =IF(C29=FALSE,FALSE,TRUE) -> FALSE
A30: =VLOOKUP('Itinerários ES por transportado'!A154,'Itinerários ES por transportado'!A:A,1,0) -> ARNALDO BENEDITO AMORIM - ME | B30: =LEFT(VLOOKUP(A30,Itinerários_ES_por_transportadora_pdf[[Transportadora]:[Rota]],2,0),2) -> ES | C30: FALSE | D30: TRUE | F30: =IF(C30=FALSE,FALSE,TRUE) -> FALSE
A31: =VLOOKUP('Itinerários MG por transportado'!A571,'Itinerários MG por transportado'!A:A,1,0) -> ARNALDO BENEDITO AMORIM - ME | B31: =LEFT(VLOOKUP(A31,'Itinerários MG por transportado'!A:B,2,0),2) -> MG | C31: FALSE | D31: TRUE | F31: =IF(C31=FALSE,FALSE,TRUE) -> FALSE
A32: =VLOOKUP('Itinerários por transportadora '!A558,'Itinerários por transportadora '!A:A,1,0) -> C J DELASARE TRANSPORTES LTDA | B32: =LEFT(VLOOKUP(A32,'Itinerários por transportadora '!A:B,2,0),2) -> SP | C32: FALSE | D32: TRUE | F32: =IF(C32=FALSE,FALSE,TRUE) -> FALSE
A33: =VLOOKUP('Itinerários RJ por transportado'!A244,'Itinerários RJ por transportado'!A:A,1,0) -> C J DELASARE TRANSPORTES LTDA | B33: =LEFT(VLOOKUP(A33,Itinerários_RJ_por_transportadora_pdf[[Transportadora]:[Rota]],2,0),2) -> RJ | C33: FALSE | D33: TRUE | F33: =IF(C33=FALSE,FALSE,TRUE) -> FALSE
A34: =VLOOKUP('Itinerários ES por transportado'!A112,'Itinerários ES por transportado'!A:A,1,0) -> C J DELASARE TRANSPORTES LTDA | B34: =LEFT(VLOOKUP(A34,Itinerários_ES_por_transportadora_pdf[[Transportadora]:[Rota]],2,0),2) -> ES | C34: FALSE | D34: TRUE | F34: =IF(C34=FALSE,FALSE,TRUE) -> FALSE
A35: =VLOOKUP('Itinerários MG por transportado'!A408,'Itinerários MG por transportado'!A:A,1,0) -> C J DELASARE TRANSPORTES LTDA | B35: =LEFT(VLOOKUP(A35,'Itinerários MG por transportado'!A:B,2,0),2) -> MG | C35: FALSE | D35: TRUE | F35: =IF(C35=FALSE,FALSE,TRUE) -> FALSE
A36: =VLOOKUP('Itinerários MG por transportado'!A97,'Itinerários MG por transportado'!A:A,1,0) -> CALL EXPRESS TRANSPORTE E LOGISTICA LTDA | B36: =LEFT(VLOOKUP(A36,'Itinerários MG por transportado'!A:B,2,0),2) -> MG | C36: FALSE | D36: TRUE | F36: =IF(C36=FALSE,FALSE,TRUE) -> FALSE
A37: =VLOOKUP('Itinerários por transportadora '!A292,'Itinerários por transportadora '!A:A,1,0) -> CARLOS ROBERTO CABRINI TRANSP. - ME | B37: =LEFT(VLOOKUP(A37,'Itinerários por transportadora '!A:B,2,0),2) -> SP | C37: FALSE | D37: TRUE | F37: =IF(C37=FALSE,FALSE,TRUE) -> FALSE
A38: =VLOOKUP('Itinerários por transportadora '!A47,'Itinerários por transportadora '!A:A,1,0) -> CARSTEN | B38: =LEFT(VLOOKUP(A38,'Itinerários por transportadora '!A:B,2,0),2) -> SP | C38: FALSE | D38: TRUE | F38: =IF(C38=FALSE,FALSE,TRUE) -> FALSE
A39: =VLOOKUP('Itinerários RJ por transportado'!A6,'Itinerários RJ por transportado'!A:A,1,0) -> CARSTEN | B39: =LEFT(VLOOKUP(A39,Itinerários_RJ_por_transportadora_pdf[[Transportadora]:[Rota]],2,0),2) -> RJ | C39: FALSE | D39: TRUE | F39: =IF(C39=FALSE,FALSE,TRUE) -> FALSE
A40: =VLOOKUP('Itinerários RJ por transportado'!A620,'Itinerários RJ por transportado'!A:A,1,0) -> CLAUDIA MOREIRA CAIRES CASTRO | B40: =LEFT(VLOOKUP(A40,Itinerários_RJ_por_transportadora_pdf[[Transportadora]:[Rota]],2,0),2) -> RJ | C40: FALSE | D40: TRUE | F40: =IF(C40=FALSE,FALSE,TRUE) -> FALSE
...
